Workbook

Sheet Song Tracker
A1: KINGS OF EWING — SONG TRACKER
A2: Song | B2: PDF | C2: Web | D2: Artist | E2: Artist Gender | F2: Duration | G2: Vocal(s) | H2: Instrument Swap | I2: Gig Ready | J2: Decade | K2: Never Played Live | L2: Total Times Played | M2: 2026-05-16 Fat Shallot | N2: 2026-05-14 Fat Shallot | O2: 2026-05-02 Lincolnwood | P2: 2026-04-22 Spring Cha Ching | Q2: 2026-01-24 Goat Village | R2: 2025-11-16 Double Clutch | S2: 2025-09-06 Block Party | T2: 2025-06-25 American Legion | U2: 2025-06-07 Fat Shallot | V2: 2025-05-03 Lincolnwood | W2: 2024-10-09 Fat Shallot | X2: 2024-09-07 Block Party | Y2: 2024-08-10 Fat Shallot | Z2: 2024-07-13 Chicago Union | AA2: 2024-06-08 Fat Shallot | AB2: 2024-04-27 Lincolnwood | AC2: 2023-09-09 Block Party
A3: Angel From Montgomery | B3: PDF | C3: Web | D3: John Prine | E3: M | F3: 0.0027662037 | G3: Miles | I3: ✓ | J3: 70s | L3: =COUNTIF(M3:AC3,"✓") -> 2 | S3: ✓ | T3: ✓
A4: Black | B4: PDF | C4: Web | D4: Pearl Jam | E4: M | F4: 0.0039583333 | G4: Drew | J4: 90s | L4: =COUNTIF(M4:AC4,"✓") -> 3 | T4: ✓ | X4: ✓ | Y4: ✓
A5: Bohemian Like You | B5: PDF | C5: Web | D5: Dandy Warhols | E5: M | F5: 0.0025810185 | G5: Matt | I5: ✓ | J5: 00s | L5: =COUNTIF(M5:AC5,"✓") -> 9 | M5: ✓ | N5: ✓ | O5: ✓ | Q5: ✓ | T5: ✓ | V5: ✓ | X5: ✓ | Y5: ✓ | AA5: ✓
A6: Come Together | B6: PDF | C6: Web | D6: The Beatles | E6: M | F6: 0.0027199074 | G6: Matt | I6: ✓ | J6: 60s | L6: =COUNTIF(M6:AC6,"✓") -> 4 | M6: ✓ | Q6: ✓ | R6: ✓ | T6: ✓
A7: Crossroads | B7: PDF | C7: Web | D7: Cream | E7: M | F7: 0.0034143519 | G7: Miles | I7: ✓ | J7: 60s | L7: =COUNTIF(M7:AC7,"✓") -> 5 | M7: ✓ | N7: ✓ | O7: ✓ | P7: ✓ | Q7: ✓
A8: Dedicated Follower Of Fashion | B8: PDF | C8: Web | D8: The King | E8: M | F8: 0.0017476852 | G8: Jack | H8: ✓ | I8: ✓ | J8: 60s | L8: =COUNTIF(M8:AC8,"✓") -> 9 | Q8: ✓ | T8: ✓ | U8: ✓ | V8: ✓ | W8: ✓ | X8: ✓ | Y8: ✓ | AA8: ✓ | AC8: ✓
A9: Don't Let Me Down | B9: PDF | C9: Web | D9: The Beatles | E9: M | F9: 0.0021875 | G9: Miles | I9: ✓ | J9: 60s | L9: =COUNTIF(M9:AC9,"✓") -> 17 | M9: ✓ | N9: ✓ | O9: ✓ | P9: ✓ | Q9: ✓ | R9: ✓ | S9: ✓ | T9: ✓ | U9: ✓ | V9: ✓ | W9: ✓ | X9: ✓ | Y9: ✓ | Z9: ✓ | AA9: ✓ | AB9: ✓ | AC9: ✓
A10: Don't Look Back In Anger | B10: PDF | C10: Web | D10: Oasis | E10: M | F10: 0.0033449074 | G10: Jack | H10: ✓ | J10: 90s | L10: =COUNTIF(M10:AC10,"✓") -> 1 | X10: ✓
A11: Down By The River | B11: PDF | C11: Web | D11: Neil Young | E11: M | F11: 0.0055555556 | G11: Miles | J11: 70s | L11: =COUNTIF(M11:AC11,"✓") -> 9 | T11: ✓ | U11: ✓ | W11: ✓ | X11: ✓ | Y11: ✓ | Z11: ✓ | AA11: ✓ | AB11: ✓ | AC11: ✓
A12: End Of The World | B12: PDF | C12: Web | D12: R.E.M. | E12: M | F12: 0.0027430556 | G12: Matt | I12: ✓ | J12: 80s | L12: =COUNTIF(M12:AC12,"✓") -> 6 | M12: ✓ | N12: ✓ | O12: ✓ | P12: ✓ | Q12: ✓ | R12: ✓
A13: Follow Your Arrow | B13: PDF | C13: Web | D13: Kasey Musgraves | E13: F | F13: 0.0023032407 | G13: Matt | I13: ✓ | J13: 10s | L13: =COUNTIF(M13:AC13,"✓") -> 2 | T13: ✓ | U13: ✓
A14: For What It's Worth | B14: PDF | C14: Web | D14: Buffalo Springfield | E14: M | F14: 0.0017708333 | G14: Miles | J14: 60s | L14: =COUNTIF(M14:AC14,"✓") -> 1 | AC14: ✓
A15: Fortunate Son | B15: PDF | C15: Web | D15: Credence Clearwater Revival | E15: M | F15: 0.0027893519 | G15: Miles | I15: ✓ | J15: 60s | L15: =COUNTIF(M15:AC15,"✓") -> 13 | M15: ✓ | N15: ✓ | O15: ✓ | Q15: ✓ | S15: ✓ | T15: ✓ | U15: ✓ | V15: ✓ | X15: ✓ | Y15: ✓ | Z15: ✓ | AA15: ✓ | AB15: ✓
A16: Found Out About You | B16: PDF | C16: Web | D16: Gin Blossom | E16: M | F16: 0.0024884259 | G16: Drew | I16: ✓ | J16: 90s | L16: =COUNTIF(M16:AC16,"✓") -> 8 | M16: ✓ | Q16: ✓ | T16: ✓ | X16: ✓ | Y16: ✓ | Z16: ✓ | AA16: ✓ | AC16: ✓
A17: From The Start | B17: PDF | C17: Web | D17: Laufey | E17: F | F17: 0.0019328704 | G17: Matt | I17: ✓ | J17: 20s | L17: =COUNTIF(M17:AC17,"✓") -> 1 | Q17: ✓
A18: Guess Again | B18: PDF | C18: Web | D18: Jeff Tweedy | E18: M | F18: 0.0024305556 | G18: Miles | I18: ✓ | J18: 20s | L18: =COUNTIF(M18:AC18,"✓") -> 8 | M18: ✓ | N18: ✓ | O18: ✓ | Q18: ✓ | R18: ✓ | S18: ✓ | T18: ✓ | U18: ✓
A19: Head Over Heels | B19: PDF | C19: Web | D19: Tears for Fears | E19: M | F19: 0.0026041667 | G19: Drew | I19: ✓ | J19: 80s | L19: =COUNTIF(M19:AC19,"✓") -> 5 | M19: ✓ | N19: ✓ | O19: ✓ | P19: ✓ | Q19: ✓
A20: Heroes | B20: PDF | C20: Web | D20: David Bowie | E20: M | F20: 0.0046875 | G20: Matt | I20: ✓ | J20: 70s | L20: =COUNTIF(M20:AC20,"✓") -> 9 | M20: ✓ | Q20: ✓ | T20: ✓ | U20: ✓ | X20: ✓ | Y20: ✓ | Z20: ✓ | AB20: ✓ | AC20: ✓
A21: I've Got A Feeling | B21: PDF | C21: Web | D21: The Beates | E21: M | F21: 0.0025115741 | G21: Miles | J21: 60s | L21: =COUNTIF(M21:AC21,"✓") -> 1 | X21: ✓
A22: Just Like Heaven | B22: PDF | C22: Web | D22: The Cure | E22: M | F22: 0.0025810185 | G22: Matt | I22: ✓ | J22: 80s | L22: =COUNTIF(M22:AC22,"✓") -> 16 | M22: ✓ | N22: ✓ | O22: ✓ | P22: ✓ | Q22: ✓ | S22: ✓ | T22: ✓ | U22: ✓ | V22: ✓ | W22: ✓ | X22: ✓ | Y22: ✓ | Z22: ✓ | AA22: ✓ | AB22: ✓ | AC22: ✓
A23: Just What I Needed | B23: PDF | C23: Web | D23: The Cars | E23: M | F23: 0.0026041667 | G23: Matt | I23: ✓ | J23: 70s | L23: =COUNTIF(M23:AC23,"✓") -> 8 | Q23: ✓ | S23: ✓ | T23: ✓ | U23: ✓ | V23: ✓ | W23: ✓ | X23: ✓ | Y23: ✓
A24: Kings Of Ewing | B24: PDF | D24: Kings of Ewing | E24: M | F24: 0.0038541667 | G24: Drew | I24: ✓ | J24: Original | L24: =COUNTIF(M24:AC24,"✓") -> 8 | N24: ✓ | Q24: ✓ | T24: ✓ | U24: ✓ | W24: ✓ | X24: ✓ | Y24: ✓ | AA24: ✓
A25: Laid | B25: PDF | C25: Web | D25: James | E25: M | F25: 0.0019791667 | G25: Jack | H25: ✓ | I25: ✓ | J25: 90s | L25: =COUNTIF(M25:AC25,"✓") -> 10 | M25: ✓ | P25: ✓ | Q25: ✓ | T25: ✓ | U25: ✓ | W25: ✓ | X25: ✓ | Y25: ✓ | Z25: ✓ | AA25: ✓
A26: Let Me Roll It | B26: PDF | C26: Web | D26: Wings | E26: M | F26: 0.002650463 | G26: Miles | I26: ✓ | J26: 70s | L26: =COUNTIF(M26:AC26,"✓") -> 1 | M26: ✓
A27: Little By Little | B27: PDF | C27: Web | D27: Oasis | E27: M | F27: 0.0030439815 | G27: Jack | H27: ✓ | I27: ✓ | J27: 00s | L27: =COUNTIF(M27:AC27,"✓") -> 2 | M27: ✓ | Q27: ✓
A28: Message In A Bottle | B28: PDF | C28: Web | D28: The Police | E28: M | F28: 0.0028587963 | G28: Drew | I28: ✓ | J28: 80s | L28: =COUNTIF(M28:AC28,"✓") -> 5 | M28: ✓ | N28: ✓ | O28: ✓ | Q28: ✓ | R28: ✓
A29: Midnight Rider | B29: PDF | C29: Web | D29: The Allman Brothers Band | E29: M | F29: 0.0020486111 | G29: Drew | I29: ✓ | J29: 70s | L29: =COUNTIF(M29:AC29,"✓") -> 12 | M29: ✓ | Q29: ✓ | R29: ✓ | T29: ✓ | U29: ✓ | V29: ✓ | W29: ✓ | X29: ✓ | Y29: ✓ | Z29: ✓ | AA29: ✓ | AB29: ✓
A30: No One To Depend On | B30: PDF | C30: Web | D30: Santana | E30: M | F30: 0.003599537 | G30: Matt | I30: ✓ | J30: 70s | L30: =COUNTIF(M30:AC30,"✓") -> 15 | M30: ✓ | N30: ✓ | O30: ✓ | P30: ✓ | Q30: ✓ | R30: ✓ | S30: ✓ | T30: ✓ | U30: ✓ | V30: ✓ | W30: ✓ | X30: ✓ | Y30: ✓ | Z30: ✓ | AA30: ✓
A31: Octopus's Garden | B31: PDF | C31: Web | D31: The Beatles | E31: M | F31: 0.0019675926 | G31: Jack | H31: ✓ | J31: 60s | L31: =COUNTIF(M31:AC31,"✓") -> 2 | X31: ✓ | AC31: ✓
A32: Ohio | B32: PDF | C32: Web | D32: CSNY | E32: M | F32: 0.0032291667 | G32: Miles | I32: ✓ | J32: 70s | L32: =COUNTIF(M32:AC32,"✓") -> 7 | M32: ✓ | Q32: ✓ | T32: ✓ | X32: ✓ | Y32: ✓ | Z32: ✓ | AA32: ✓
A33: Pink Pony Club | B33: PDF | C33: Web | D33: Chappel Roan | E33: F | F33: 0.0029513889 | G33: Matt | I33: ✓ | J33: 20s | L33: =COUNTIF(M33:AC33,"✓") -> 12 | M33: ✓ | N33: ✓ | O33: ✓ | P33: ✓ | Q33: ✓ | R33: ✓ | S33: ✓ | T33: ✓ | U33: ✓ | V33: ✓ | W33: ✓ | X33: ✓
A34: Riders On The Storm | B34: PDF | C34: Web | D34: The Door | E34: M | F34: 0.0041319444 | G34: Miles | J34: 70s | L34: =COUNTIF(M34:AC34,"✓") -> 8 | Q34: ✓ | S34: ✓ | T34: ✓ | U34: ✓ | X34: ✓ | Y34: ✓ | AA34: ✓ | AB34: ✓
A35: Rockin' In The Free World | B35: PDF | C35: Web | D35: Neil Young | E35: M | F35: 0.0059606481 | G35: Miles | I35: ✓ | J35: 80s | L35: =COUNTIF(M35:AC35,"✓") -> 9 | M35: ✓ | Q35: ✓ | T35: ✓ | U35: ✓ | V35: ✓ | X35: ✓ | Y35: ✓ | AA35: ✓ | AB35: ✓
A36: Seven Nation Army | B36: PDF | C36: Web | D36: White Stripes | E36: M | F36: 0.0024305556 | G36: Drew | J36: 00s | L36: =COUNTIF(M36:AC36,"✓") -> 4 | O36: ✓ | X36: ✓ | Y36: ✓ | AB36: ✓
A37: Smooth Operator | B37: PDF | C37: Web | D37: Sade | E37: F | F37: 0.0033680556 | G37: Drew | I37: ✓ | J37: 80s | L37: =COUNTIF(M37:AC37,"✓") -> 9 | M37: ✓ | N37: ✓ | O37: ✓ | Q37: ✓ | R37: ✓ | S37: ✓ | T37: ✓ | U37: ✓ | V37: ✓
A38: Starlight | B38: PDF | C38: Web | D38: Muse | E38: M | F38: 0.0026041667 | G38: Drew | I38: ✓ | J38: 00s | L38: =COUNTIF(M38:AC38,"✓") -> 5 | M38: ✓ | N38: ✓ | O38: ✓ | P38: ✓ | Q38: ✓
A39: Sympathy For The Devil | B39: PDF | C39: Web | D39: Rolling Stones | E39: M | F39: 0.0034722222 | G39: Nate | J39: 60s | L39: =COUNTIF(M39:AC39,"✓") -> 2 | X39: ✓ | Y39: ✓
A40: Teach Your Children | B40: PDF | C40: Web | D40: CSNY | E40: M | F40: 0.0020023148 | G40: Miles | J40: 70s | L40: =COUNTIF(M40:AC40,"✓") -> 1 | R40: ✓
...

Sheet Gig Tracker
A1: KINGS OF EWING — GIG LOG
A2: Date | B2: Time | C2: Venue | D2: Event | E2: # Songs | F2: Gig Length | G2: Venue Name | H2: Venue Email | I2: Event Name | J2: Event Email | K2: Pay | L2: Notes
A3: 2023-09-09 | B3: 5:00 PM | C3: Block Party | D3: Ewing Block Party | E3: 10
A4: 2024-04-27 | B4: 6:00 PM | C4: Lincolnwood | D4: Spring Fling | E4: 11
A5: 2024-06-08 | B5: 6:00 PM | C5: Fat Shallot | E5: 16 | G5: Fat Shallot | H5: info@thefatshallot.com
A6: 2024-07-13 | B6: 6:00 PM | C6: Chicago Union | D6: Chicago Union FC | E6: 11 | G6: J.A. Cohen (Jeff) | H6: jacohenmusic@gmail.com | K6: 100
A7: 2024-08-10 | B7: 6:00 PM | C7: Fat Shallot | E7: 21 | G7: Fat Shallot | H7: info@thefatshallot.com
A8: 2024-09-07 | B8: 5:00 PM | C8: Block Party | D8: Ewing Block Party | E8: 26
A9: 2024-10-09 | B9: 6:00 PM | C9: Fat Shallot | D9: Covenant Nursery Dining for Dollars | E9: 11 | G9: Fat Shallot | H9: info@thefatshallot.com
A10: 2025-05-03 | B10: 6:00 PM | C10: Lincolnwood | D10: Spring Fling | E10: 13
A11: 2025-06-07 | B11: 6:00 PM | C11: Fat Shallot | E11: 19 | G11: Fat Shallot | H11: info@thefatshallot.com
A12: 2025-06-25 | B12: 6:00 PM | C12: American Legion | E12: 28
A13: 2025-09-06 | B13: 5:00 PM | C13: Block Party | D13: Ewing Block Party | E13: 14
A14: 2025-10-18 | C14: Mack's Bike & Goods | G14: Kelly Mack | H14: kelly@macksbikeandgoods.com | L14: Cancelled due to weather
A15: 2025-11-16 | B15: 7:00 PM | C15: Double Clutch | D15: Bundled Blessings Fundraiser | E15: 13 | F15: 60 | G15: Nick Murray | H15: nmurray@doubleclutchbrewing.com | I15: Krys Juleen | J15: krys@faithatfirst.com
A16: 2026-01-24 | B16: 7:00 PM | C16: Goat Village | E16: 31 | G16: Goat Village | H16: goatvillage777@gmail.com
A17: 2026-04-22 | B17: 6:00 PM | C17: American Legion | D17: Spring Cha Ching | E17: 10 | F17: 45
A18: 2026-05-02 | B18: 6:00 PM | C18: Lincolnwood | D18: Spring Fling | E18: 16 | F18: 75
A19: 2026-05-14 | B19: 5:30 PM | C19: Fat Shallot | D19: Covenant Nursery Dining for Dollars | E19: 16 | F19: 75 | G19: Fat Shallot | H19: info@thefatshallot.com | I19: Kim Stanton | J19: kims@covenantnurseryschool.org
A20: 2026-05-16 | B20: 7:00 PM | C20: Fat Shallot | D20: Greg's 40th Birthday | F20: 120 | G20: Fat Shallot | H20: info@thefatshallot.com | I20: Jenny Sprenzel | J20: Jenny.Sprenzel@rushortho.com | K20: 250
A21: 46194 | B21: 0.70833333 | C21: Chicago Union | D21: Chicago Union FC | G21: J.A. Cohen (Jeff) | H21: jacohenmusic@gmail.com
A22: 46197 | B22: 0.75 | C22: Ridgeville Parks | G22: Natalie Sallee | H22: programs@ridgeville.org

Sheet Potential Songs
A1: KINGS OF EWING — POTENTIAL SONGS
A2: song | B2: artist | C2: who suggested it | D2: decade | E2: notes | F2: web url
A3: Cortez the Killer | B3: Neil Young | C3: Matt | D3: 70s | E3: Down By the River replacement | F3: https://tabs.ultimate-guitar.com/tab/neil-young/cortez-the-killer-official-2878016
A4: Short Skirt/Long Jacket | B4: Cake | C4: Drea | D4: 00s | E4: Matt will sing | F4: https://tabs.ultimate-guitar.com/tab/cake/short-skirt-long-jacket-official-2175899
A5: Blinding Lights | B5: The Weeknd | C5: Drew | D5: 20s | F5: https://tabs.ultimate-guitar.com/tab/the-weeknd/blinding-lights-official-3018305
A6: Electric Feel | B6: MGMT | C6: Drew | D6: 00s | E6: Miles could sing — needs falsetto. 90% about finding right patches for Matt | F6: https://tabs.ultimate-guitar.com/tab/mgmt/electric-feel-official-2099683
A7: Sunny Afternoon | B7: The Kinks | C7: Jack | F7: https://tabs.ultimate-guitar.com/tab/the-kinks/sunny-afternoon-official-2139793
A8: Honest Mistake | B8: The Bravery | C8: Jack

Sheet Potential Gigs
A1: KINGS OF EWING — POTENTIAL GIGS
A2: Venue | B2: Name | C2: Email | D2: Date Reached Out | E2: Proposed Date | F2: Status | G2: Notes
A3: Downtown Evanston | B3: Andy Vick | C3: avick@downtownevanston.org | D3: 2025-05-05 | F3: Waiting | G3: Puts music line-up together in January — follow up Jan 2026
A4: Stippler Block Party | B4: Nicole Stippler | C4: nicole@stippler.com | D4: 2025-09-02 | E4: 2025-09-06 | F4: Waiting | G4: Saw us at Lincolnwood Spring Fling. Last minute inquiry for block party closer. Asked about rates and availability.

Sheet Expenses
A1: KINGS OF EWING — FINANCES
A2: Date | B2: Description | C2: Paid By | D2: Amount | E2: Notes
A3: 45486 | B3: gig fee | C3: Chicago Union | D3: 100
A4: 46158 | B4: gig fee | C4: Jenny Sprenzel | D4: 250

Sheet 2026-06-24 Ridgeville Parks
A1: 2026-06-24 — Ridgeville Parks District — 6:00 PM
A2: # | B2: Song | C2: PDF | D2: Web | E2: Vocals | F2: Duration
B4: Total Set Length | F4: =SUM(F3:F3) -> 0

Sheet 2026-06-21 Chicago Union
A1: 2026-06-21 — Chicago Union FC — ETHS Lazier Field — 5:00 PM
A2: # | B2: Song | C2: PDF | D2: Web | E2: Vocals | F2: Duration
B4: Total Set Length | F4: =SUM(F3:F3) -> 0

Sheet 2026-05-16 Fat Shallot
A1: 2026-05-16 — Fat Shallot — 7:00-9:00 PM
A2: # | B2: Song | C2: PDF | D2: Web | E2: Vocals | F2: Duration
A3: 1 | B3: Don't Let Me Down | C3: PDF | D3: Web | E3: Miles | F3: 0.0021875
A4: 2 | B4: The Seeker | C4: PDF | D4: Web | E4: Drew | F4: 0.0022569444
A5: 3 | B5: Let Me Roll It | C5: PDF | D5: Web | E5: Miles | F5: 0.002650463
A6: 4 | B6: Walk On | C6: PDF | D6: Web | E6: Miles | F6: 0.0020833333
A7: 5 | B7: Midnight Rider | C7: PDF | D7: Web | E7: Drew | F7: 0.0020486111
A8: 6 | B8: Crossroads | C8: PDF | D8: Web | E8: Miles | F8: 0.0034143519
A9: 7 | B9: Found Out About You | C9: PDF | D9: Web | E9: Drew | F9: 0.0024884259
A10: 8 | B10: No One To Depend On | C10: PDF | D10: Web | E10: Matt | F10: 0.003599537
A11: 9 | B11: Won't Back Down | C11: PDF | D11: Web | E11: Miles | F11: 0.0020949074
A12: 10 | B12: Bohemian Like You | C12: PDF | D12: Web | E12: Matt | F12: 0.0025810185
A13: 11 | B13: Message In A Bottle | C13: PDF | D13: Web | E13: Drew | F13: 0.0028587963
A14: 12 | B14: Guess Again | C14: PDF | D14: Web | E14: Miles | F14: 0.0024305556
... A16: 14 | B16: Whipping Post | C16: PDF | D16: Web | E16: Drew | F16: 0.0033217593
A17: BREAK
A18: 15 | B18: Come Together | C18: PDF | D18: Web | E18: Matt | F18: 0.0027199074
A19: 16 | B19: Fortunate Son | C19: PDF | D19: Web | E19: Miles | F19: 0.0027893519
A20: 17 | B20: Smooth Operator | C20: PDF | D20: Web | E20: Drew | F20: 0.0033680556
A21: 18 | B21: Pink Pony Club | C21: PDF | D21: Web | E21: Matt | F21: 0.0029513889
A22: 19 | B22: Head Over Heels | C22: PDF | D22: Web | E22: Drew | F22: 0.0026041667
A23: 20 | B23: Ohio | C23: PDF | D23: Web | E23: Miles | F23: 0.0032291667
A24: 21 | B24: End Of The World | C24: PDF | D24: Web | E24: Matt | F24: 0.0027430556
A25: 22 | B25: Starlight | C25: PDF | D25: Web | E25: Drew | F25: 0.0026041667
A26: 23 | B26: Laid | C26: PDF | D26: Web | E26: Jack | F26: 0.0019791667
A27: 24 | B27: Just Like Heaven | C27: PDF | D27: Web | E27: Matt | F27: 0.0025810185
A28: 25 | B28: Heroes | C28: PDF | D28: Web | E28: Matt | F28: 0.0046875
A29: 26 | B29: Rockin' In The Free World | C29: PDF | D29: Web | E29: Miles | F29: 0.0059606481
B30: Total Set Length | F30: =SUM(F3:F16,F18:F29) -> 0.075277778

Sheet 2026-05-14 Fat Shallot
A1: 2026-05-14 — Fat Shallot — 5:30 PM
A2: # | B2: Song | C2: PDF | D2: Web | E2: Vocals | F2: Duration
A3: 1 | B3: Don't Let Me Down | C3: PDF | D3: Web | E3: Miles | F3: 0.0021875
A4: 2 | B4: Pink Pony Club | C4: PDF | D4: Web | E4: Matt | F4: 0.0029513889
A5: 3 | B5: Head Over Heels | C5: PDF | D5: Web | E5: Drew | F5: 0.0026041667
A6: 4 | B6: Just Like Heaven | C6: PDF | D6: Web | E6: Matt | F6: 0.0025810185
A7: 5 | B7: Guess Again | C7: PDF | D7: Web | E7: Miles | F7: 0.0024305556
A8: 6 | B8: Message In A Bottle | C8: PDF | D8: Web | E8: Drew | F8: 0.0028587963
A9: 7 | B9: Crossroads | C9: PDF | D9: Web | E9: Miles | F9: 0.0034143519
A10: 8 | B10: Kings Of Ewing | C10: PDF | E10: Drew | F10: =VLOOKUP(B10,'Song Tracker'!$A$3:$F$48,6,FALSE) -> 0.0038541667
A11: 9 | B11: No One To Depend On | C11: PDF | D11: Web | E11: Matt | F11: 0.003599537
A12: 10 | B12: Fortunate Son | C12: PDF | D12: Web | E12: Miles | F12: 0.0027893519
A13: 11 | B13: Smooth Operator | C13: PDF | D13: Web | E13: Drew | F13: 0.0033680556
A14: 12 | B14: Bohemian Like You | C14: PDF | D14: Web | E14: Matt | F14: 0.0025810185
A15: 13 | B15: Starlight | C15: PDF | D15: Web | E15: Drew | F15: 0.0026041667
A16: 14 | B16: End Of The World | C16: PDF | D16: Web | E16: Matt | F16: 0.0027430556
A17: 15 | B17: Won't Back Down | C17: PDF | D17: Web | E17: Miles | F17: 0.0020949074
A18: 16 | B18: Whipping Post | C18: PDF | D18: Web | E18: Drew | F18: 0.0033217593
B20: Total Set Length | F20: =SUM(F3:F19) -> 0.045983796

Sheet 2026-05-02 Lincolnwood
A1: 2026-05-02 — Lincolnwood PTA Spring Fling
A2: # | B2: Song | C2: PDF | D2: Web | E2: Vocals | F2: Duration
A3: opener | B3: Seven Nation Army | C3: PDF | D3: Web | E3: Drew | F3: =VLOOKUP(B3,'Song Tracker'!$A$3:$F$48,6,FALSE) -> 0.0024305556
A4: 1 | B4: Don't Let Me Down | C4: PDF | D4: Web | E4: Miles | F4: 0.0021875
A5: 2 | B5: Pink Pony Club | C5: PDF | D5: Web | E5: Matt | F5: 0.0029513889
A6: 3 | B6: Head Over Heels | C6: PDF | D6: Web | E6: Drew | F6: 0.0026041667
A7: 4 | B7: Just Like Heaven | C7: PDF | D7: Web | E7: Matt | F7: 0.0025810185
A8: 5 | B8: Guess Again | C8: PDF | D8: Web | E8: Miles | F8: 0.0024305556
A9: 6 | B9: Message In A Bottle | C9: PDF | D9: Web | E9: Drew | F9: 0.0028587963
A10: 7 | B10: Crossroads | C10: PDF | D10: Web | E10: Miles | F10: 0.0034143519
A12: 9 | B12: No One To Depend On | C12: PDF | D12: Web | E12: Matt | F12: 0.003599537
A13: 10 | B13: Fortunate Son | C13: PDF | D13: Web | E13: Miles | F13: 0.0027893519
A14: 11 | B14: Smooth Operator | C14: PDF | D14: Web | E14: Drew | F14: 0.0033680556
A15: 12 | B15: Bohemian Like You | C15: PDF | D15: Web | E15: Matt | F15: 0.0025810185
A16: 13 | B16: Starlight | C16: PDF | D16: Web | E16: Drew | F16: 0.0026041667
... A19: 16 | B19: Whipping Post | C19: PDF | D19: Web | E19: Drew | F19: 0.0033217593
B21: Total Set Length | F21: =SUM(F3:F20) -> 0.044560185

Sheet 2026-04-22 Spring Cha Ching
A1: 2026-04-22 — American Legion (D65 Spring Cha Ching)
A2: # | B2: Song | C2: PDF | D2: Web | E2: Vocals | F2: Duration
A3: 1 | B3: Don't Let Me Down | C3: PDF | D3: Web | E3: Miles | F3: 0.0021875
A4: 2 | B4: Pink Pony Club | C4: PDF | D4: Web | E4: Matt | F4: 0.0029513889
A5: 3 | B5: Head Over Heels | C5: PDF | D5: Web | E5: Drew | F5: 0.0026041667
A6: 4 | B6: Just Like Heaven | C6: PDF | D6: Web | E6: Matt | F6: 0.0025810185
A7: 5 | B7: Crossroads | C7: PDF | D7: Web | E7: Miles | F7: 0.0034143519
A8: 6 | B8: Laid | C8: PDF | D8: Web | E8: Jack | F8: 0.0019791667
A9: 7 | B9: No One To Depend On | C9: PDF | D9: Web | E9: Matt | F9: 0.003599537
A10: 8 | B10: Starlight | C10: PDF | D10: Web | E10: Drew | F10: 0.0026041667
A11: 9 | B11: End Of The World | C11: PDF | D11: Web | E11: Matt | F11: 0.0027430556
A12: 10 | B12: Whipping Post | C12: PDF | D12: Web | E12: Drew | F12: 0.0033217593
B14: Total Set Length | F14: =SUM(F3:F13) -> 0.027986111

Sheet 2026-01-24 Goat Village
A1: 2026-01-24 — Goat Village
A2: # | B2: Song | C2: PDF | D2: Web | E2: Vocals | F2: Duration
A3: 1 | B3: Don't Let Me Down | C3: PDF | D3: Web | E3: Miles | F3: 0.0021875
A4: 2 | B4: Found Out About You | C4: PDF | D4: Web | E4: Drew | F4: 0.0024884259
A5: 3 | B5: Ohio | C5: PDF | D5: Web | E5: Miles | F5: 0.0032291667
A6: 4 | B6: Laid | C6: PDF | D6: Web | E6: Jack | F6: 0.0019791667
A7: 5 | B7: Little By Little | C7: PDF | D7: Web | E7: Jack | F7: 0.0030439815
A8: 6 | B8: End Of The World | C8: PDF | D8: Web | E8: Matt | F8: 0.0027430556
A9: 7 | B9: Just Like Heaven | C9: PDF | D9: Web | E9: Matt | F9: 0.0025810185
A10: 8 | B10: Head Over Heels | C10: PDF | D10: Web | E10: Drew | F10: 0.0026041667
A11: 9 | B11: From The Start | C11: PDF | D11: Web | E11: Matt | F11: 0.0019328704
A12: 10 | B12: That's What I Love | C12: PDF | D12: Web | E12: Drew | F12: 0.0034606481
A13: 11 | B13: No One To Depend On | C13: PDF | D13: Web | E13: Matt | F13: 0.003599537
A14: 12 | B14: Smooth Operator | C14: PDF | D14: Web | E14: Drew | F14: 0.0033680556
... A22: 20 | B22: Bohemian Like You | C22: PDF | D22: Web | E22: Matt | F22: 0.0025810185
A23: 21 | B23: Kings Of Ewing | C23: PDF | E23: Drew | F23: 0.0038541667
A24: 22 | B24: Riders On The Storm | C24: PDF | D24: Web | E24: Miles | F24: 0.0041319444
A25: 23 | B25: Midnight Rider | C25: PDF | D25: Web | E25: Drew | F25: 0.0020486111
A26: 24 | B26: Heroes | C26: PDF | D26: Web | E26: Matt | F26: 0.0046875
A27: 25 | B27: Dedicated Follower Of Fashion | C27: PDF | D27: Web | E27: Jack | F27: 0.0017476852
A28: 26 | B28: Come Together | C28: PDF | D28: Web | E28: Matt | F28: 0.0027199074
A29: 27 | B29: Message In A Bottle | C29: PDF | D29: Web | E29: Drew | F29: 0.0028587963
A30: 28 | B30: Just What I Needed | D30: Web | E30: Matt | F30: =VLOOKUP(B30,'Song Tracker'!$A$3:$F$48,6,FALSE) -> 0.0026041667
A31: 29 | B31: Rockin' In The Free World | C31: PDF | D31: Web | E31: Miles | F31: 0.0059606481
A32: 30 | B32: Guess Again | C32: PDF | D32: Web | E32: Miles | F32: 0.0024305556
A33: 31 | B33: Voodoo Child | C33: PDF | D33: Web | E33: Drew | F33: =VLOOKUP(B33,'Song Tracker'!$A$3:$F$48,6,FALSE) -> 0.0034722222
B35: Total Set Length | F35: =SUM(F3:F34) -> 0.091747685

Sheet 2025-11-16 Double Clutch
A1: 2025-11-16 — Double Clutch (Bundled Blessings Fundraiser)
A2: # | B2: Song | C2: PDF | D2: Web | E2: Vocals | F2: Duration
A3: 1 | B3: Message In A Bottle | C3: PDF | D3: Web | E3: Drew | F3: 0.0028587963
A4: 2 | B4: Don't Let Me Down | C4: PDF | D4: Web | E4: Miles | F4: 0.0021875
A5: 3 | B5: Come Together | C5: PDF | D5: Web | E5: Matt | F5: 0.0027199074
A6: 4 | B6: Smooth Operator | C6: PDF | D6: Web | E6: Drew | F6: 0.0033680556
A7: 5 | B7: Teach Your Children | C7: PDF | D7: Web | E7: Miles | F7: =VLOOKUP(B7,'Song Tracker'!$A$3:$F$48,6,FALSE) -> 0.0020023148
A8: 6 | B8: Pink Pony Club | C8: PDF | D8: Web | E8: Matt | F8: 0.0029513889
A9: 7 | B9: The Seeker | C9: PDF | D9: Web | E9: Drew | F9: 0.0022569444
A10: 8 | B10: Guess Again | C10: PDF | D10: Web | E10: Miles | F10: 0.0024305556
A11: 9 | B11: No One To Depend On | C11: PDF | D11: Web | E11: Matt | F11: 0.003599537
A12: 10 | B12: Walk On | C12: PDF | D12: Web | E12: Miles | F12: =VLOOKUP(B12,'Song Tracker'!$A$3:$F$48,6,FALSE) -> 0.0020833333
A13: 11 | B13: End Of The World | C13: PDF | D13: Web | E13: Matt | F13: 0.0027430556
A14: 12 | B14: Midnight Rider | C14: PDF | D14: Web | E14: Drew | F14: 0.0020486111
A15: 13 | B15: Whipping Post | C15: PDF | D15: Web | E15: Drew | F15: 0.0033217593
B17: Total Set Length | F17: =SUM(F3:F16) -> 0.034571759

Sheet 2025-09-06 Block Party
A1: 2025-09-06 — Ewing Block Party
A2: # | B2: Song | C2: PDF | D2: Web | E2: Vocals | F2: Duration
A3: 1 | B3: Don't Let Me Down | C3: PDF | D3: Web | E3: Miles | F3: 0.0021875
A4: 2 | B4: Just Like Heaven | C4: PDF | D4: Web | E4: Matt | F4: 0.0025810185
A5: 3 | B5: Pink Pony Club | C5: PDF | D5: Web | E5: Matt | F5: 0.0029513889
A6: 5 | B6: Smooth Operator | C6: PDF | D6: Web | E6: Drew | F6: 0.0033680556
A7: 6 | B7: Angel From Montgomery | E7: Miles | F7: =VLOOKUP(B7,'Song Tracker'!$A$3:$F$48,6,FALSE) -> 0.0027662037
A8: 7 | B8: Guess Again | C8: PDF | D8: Web | E8: Miles | F8: 0.0024305556
A9: 8 | B9: Won't Back Down | C9: PDF | D9: Web | E9: Miles | F9: 0.0020949074
A10: 9 | B10: Fortunate Son | C10: PDF | D10: Web | E10: Miles | F10: 0.0027893519
A11: 10 | B11: No One To Depend On | C11: PDF | D11: Web | E11: Matt | F11: 0.003599537
A12: 11 | B12: Just What I Needed | D12: Web | E12: Matt | F12: =VLOOKUP(B12,'Song Tracker'!$A$3:$F$48,6,FALSE) -> 0.0026041667
A13: 12 | B13: Riders On The Storm | C13: PDF | D13: Web | E13: Miles | F13: 0.0041319444
A14: 13 | B14: Walk On | C14: PDF | D14: Web | E14: Miles | F14: =VLOOKUP(B14,'Song Tracker'!$A$3:$F$48,6,FALSE) -> 0.0020833333
A15: 14 | B15: Whipping Post | C15: PDF | D15: Web | E15: Drew | F15: 0.0033217593
A16: 15 | B16: Who's That Lady | E16: Instrumental
B18: Total Set Length | F18: =SUM(F3:F17) -> 0.036909722

Sheet 2025-06-25 American Legion
A1: 2025-06-25 — American Legion
A2: # | B2: Song | C2: PDF | D2: Web | E2: Vocals | F2: Duration
A3: 1 | B3: Don't Let Me Down | C3: PDF | D3: Web | E3: Miles | F3: 0.0021875
A4: 2 | B4: Just Like Heaven | C4: PDF | D4: Web | E4: Matt | F4: 0.0025810185
A5: 3 | B5: Pink Pony Club | C5: PDF | D5: Web | E5: Matt | F5: 0.0029513889
A6: 4 | B6: Down By The River | C6: PDF | D6: Web | E6: Miles | F6: =VLOOKUP(B6,'Song Tracker'!$A$3:$F$48,6,FALSE) -> 0.0055555556
A7: 5 | B7: Smooth Operator | C7: PDF | D7: Web | E7: Drew | F7: 0.0033680556
A8: 6 | B8: That's What I Love | C8: PDF | D8: Web | E8: Drew | F8: 0.0034606481
A9: 7 | B9: Ohio | C9: PDF | D9: Web | E9: Miles | F9: 0.0032291667
A10: 8 | B10: Angel From Montgomery | E10: Miles | F10: =VLOOKUP(B10,'Song Tracker'!$A$3:$F$48,6,FALSE) -> 0.0027662037
A11: 9 | B11: Guess Again | C11: PDF | D11: Web | E11: Miles | F11: 0.0024305556
A12: 10 | B12: Follow Your Arrow | C12: PDF | D12: Web | E12: Matt | F12: =VLOOKUP(B12,'Song Tracker'!$A$3:$F$48,6,FALSE) -> 0.0023032407
A13: 11 | B13: Won't Back Down | C13: PDF | D13: Web | E13: Miles | F13: 0.0020949074
A14: 12 | B14: Midnight Rider | C14: PDF | D14: Web | E14: Drew | F14: 0.0020486111
A15: 13 | B15: The Seeker | C15: PDF | D15: Web | E15: Drew | F15: 0.0022569444
A16: 14 | B16: Fortunate Son | C16: PDF | D16: Web | E16: Miles | F16: 0.0027893519
A17: 15 | B17: No One To Depend On | C17: PDF | D17: Web | E17: Matt | F17: 0.003599537
A18: 16 | B18: Found Out About You | C18: PDF | D18: Web | E18: Drew | F18: 0.0024884259
A19: 17 | B19: Just What I Needed | D19: Web | E19: Matt | F19: =VLOOKUP(B19,'Song Tracker'!$A$3:$F$48,6,FALSE) -> 0.0026041667
A20: 18 | B20: Laid | C20: PDF | D20: Web | E20: Jack | F20: 0.0019791667
A21: 19 | B21: Dedicated Follower Of Fashion | C21: PDF | D21: Web | E21: Jack | F21: 0.0017476852
A22: 20 | B22: Bohemian Like You | C22: PDF | D22: Web | E22: Matt | F22: 0.0025810185
A23: 21 | B23: Riders On The Storm | C23: PDF | D23: Web | E23: Miles | F23: 0.0041319444
A24: 22 | B24: Kings Of Ewing | C24: PDF | E24: Drew | F24: 0.0038541667
A25: 23 | B25: Black | C25: PDF | D25: Web | E25: Drew | F25: =VLOOKUP(B25,'Song Tracker'!$A$3:$F$48,6,FALSE) -> 0.0039583333
A26: 24 | B26: Come Together | C26: PDF | D26: Web | E26: Matt | F26: 0.0027199074
A27: 25 | B27: Walk On | C27: PDF | D27: Web | E27: Miles | F27: =VLOOKUP(B27,'Song Tracker'!$A$3:$F$48,6,FALSE) -> 0.0020833333
A28: 26 | B28: Heroes | C28: PDF | D28: Web | E28: Matt | F28: 0.0046875
A29: 27 | B29: Whipping Post | C29: PDF | D29: Web | E29: Drew | F29: 0.0033217593
A30: 28 | B30: Rockin' In The Free World | C30: PDF | D30: Web | E30: Miles | F30: 0.0059606481
B32: Total Set Length | F32: =SUM(F3:F31) -> 0.085740741

Sheet 2025-06-07 Fat Shallot
A1: 2025-06-07 — Fat Shallot
A2: # | B2: Song | C2: PDF | D2: Web | E2: Vocals | F2: Duration
A3: 1 | B3: Don't Let Me Down | C3: PDF | D3: Web | E3: Miles | F3: 0.0021875
A4: 2 | B4: Just Like Heaven | C4: PDF | D4: Web | E4: Matt | F4: 0.0025810185
A5: 3 | B5: Pink Pony Club | C5: PDF | D5: Web | E5: Matt | F5: 0.0029513889
A6: 4 | B6: Down By The River | C6: PDF | D6: Web | E6: Miles | F6: =VLOOKUP(B6,'Song Tracker'!$A$3:$F$48,6,FALSE) -> 0.0055555556
A7: 5 | B7: Smooth Operator | C7: PDF | D7: Web | E7: Drew | F7: 0.0033680556
A8: 6 | B8: That's What I Love | C8: PDF | D8: Web | E8: Drew | F8: 0.0034606481
A9: 7 | B9: Follow Your Arrow | C9: PDF | D9: Web | E9: Matt | F9: =VLOOKUP(B9,'Song Tracker'!$A$3:$F$48,6,FALSE) -> 0.0023032407
A10: 8 | B10: Midnight Rider | C10: PDF | D10: Web | E10: Drew | F10: 0.0020486111
A11: 9 | B11: Guess Again | C11: PDF | D11: Web | E11: Miles | F11: 0.0024305556
A12: 10 | B12: The Seeker | C12: PDF | D12: Web | E12: Drew | F12: 0.0022569444
A13: 11 | B13: Fortunate Son | C13: PDF | D13: Web | E13: Miles | F13: 0.0027893519
A14: 12 | B14: No One To Depend On | C14: PDF | D14: Web | E14: Matt | F14: 0.003599537
A15: 13 | B15: Just What I Needed | D15: Web | E15: Matt | F15: =VLOOKUP(B15,'Song Tracker'!$A$3:$F$48,6,FALSE) -> 0.0026041667
A16: 14 | B16: Laid | C16: PDF | D16: Web | E16: Jack | F16: 0.0019791667
A17: 15 | B17: Dedicated Follower Of Fashion | C17: PDF | D17: Web | E17: Jack | F17: 0.0017476852
A18: 16 | B18: Riders On The Storm | C18: PDF | D18: Web | E18: Miles | F18: 0.0041319444
A19: 17 | B19: Kings Of Ewing | C19: PDF | E19: Drew | F19: 0.0038541667
A20: 18 | B20: Heroes | C20: PDF | D20: Web | E20: Matt | F20: 0.0046875
A21: 19 | B21: Whipping Post | C21: PDF | D21: Web | E21: Drew | F21: 0.0033217593
A22: *encore | B22: Rockin' In The Free World | C22: PDF | D22: Web | E22: Miles | F22: 0.0059606481
B24: Total Set Length | F24: =SUM(F3:F23) -> 0.063819444

Sheet 2025-05-03 Lincolnwood
A1: 2025-05-03 — Lincolnwood PTA Spring Fling
A2: # | B2: Song | C2: PDF | D2: Web | E2: Vocals | F2: Duration
A3: 1 | B3: Walk On | C3: PDF | D3: Web | E3: Miles | F3: =VLOOKUP(B3,'Song Tracker'!$A$3:$F$48,6,FALSE) -> 0.0020833333
A4: 2 | B4: Pink Pony Club | C4: PDF | D4: Web | E4: Matt | F4: 0.0029513889
A5: 3 | B5: Just Like Heaven | C5: PDF | D5: Web | E5: Matt | F5: 0.0025810185
A6: 4 | B6: No One To Depend On | C6: PDF | D6: Web | E6: Matt | F6: 0.003599537
A7: 5 | B7: Dedicated Follower Of Fashion | C7: PDF | D7: Web | E7: Jack | F7: 0.0017476852
A8: 6 | B8: Smooth Operator | C8: PDF | D8: Web | E8: Drew | F8: 0.0033680556
A9: 7 | B9: Fortunate Son | C9: PDF | D9: Web | E9: Miles | F9: 0.0027893519
A10: 8 | B10: Just What I Needed | D10: Web | E10: Matt | F10: =VLOOKUP(B10,'Song Tracker'!$A$3:$F$48,6,FALSE) -> 0.0026041667
A11: 9 | B11: Don't Let Me Down | C11: PDF | D11: Web | E11: Miles | F11: 0.0021875
A12: 10 | B12: Midnight Rider | C12: PDF | D12: Web | E12: Drew | F12: 0.0020486111
A13: 11 | B13: The Seeker | C13: PDF | D13: Web | E13: Drew | F13: 0.0022569444
A14: 12 | B14: Bohemian Like You | C14: PDF | D14: Web | E14: Matt | F14: 0.0025810185
A15: 13 | B15: Whipping Post | C15: PDF | D15: Web | E15: Drew | F15: 0.0033217593
A16: encore | B16: Rockin' In The Free World | C16: PDF | D16: Web | E16: Miles | F16: 0.0059606481
B18: Total Set Length | F18: =SUM(F3:F17) -> 0.040081019

Sheet 2024-10-09 Fat Shallot
A1: 2024-10-09 — Fat Shallot (Covenant Nursery Dining for Dollars)
A2: # | B2: Song | C2: PDF | D2: Web | E2: Vocals | F2: Duration
A3: 1 | B3: Don't Let Me Down | C3: PDF | D3: Web | E3: Miles | F3: 0.0021875
A4: 2 | B4: Just Like Heaven | C4: PDF | D4: Web | E4: Matt | F4: 0.0025810185
A5: 3 | B5: Laid | C5: PDF | D5: Web | E5: Jack | F5: 0.0019791667
A6: 4 | B6: No One To Depend On | C6: PDF | D6: Web | E6: Matt | F6: 0.003599537
A7: 5 | B7: Down By The River | C7: PDF | D7: Web | E7: Miles | F7: =VLOOKUP(B7,'Song Tracker'!$A$3:$F$48,6,FALSE) -> 0.0055555556
A8: 6 | B8: Pink Pony Club | C8: PDF | D8: Web | E8: Matt | F8: 0.0029513889
A9: 7 | B9: Kings Of Ewing | C9: PDF | E9: Drew | F9: 0.0038541667
A10: 8 | B10: Midnight Rider | C10: PDF | D10: Web | E10: Drew | F10: 0.0020486111
A11: 9 | B11: Just What I Needed | D11: Web | E11: Matt | F11: =VLOOKUP(B11,'Song Tracker'!$A$3:$F$48,6,FALSE) -> 0.0026041667
A12: 10 | B12: Dedicated Follower Of Fashion | C12: PDF | D12: Web | E12: Jack | F12: 0.0017476852
A13: 11 | B13: Whipping Post | C13: PDF | D13: Web | E13: Drew | F13: 0.0033217593
B15: Total Set Length | F15: =SUM(F3:F14) -> 0.032430556

Sheet 2024-09-07 Block Party
A1: 2024-09-07 — Ewing Block Party
A2: # | B2: Song | C2: PDF | D2: Web | E2: Vocals | F2: Duration
A3: 1 | B3: Don't Let Me Down | C3: PDF | D3: Web | E3: Miles | F3: 0.0021875
A4: 2 | B4: Won't Back Down | C4: PDF | D4: Web | E4: Miles | F4: 0.0020949074
A5: 3 | B5: No One To Depend On | C5: PDF | D5: Web | E5: Matt | F5: 0.003599537
A6: 4 | B6: Found Out About You | C6: PDF | D6: Web | E6: Drew | F6: 0.0024884259
A7: 5 | B7: Laid | C7: PDF | D7: Web | E7: Jack | F7: 0.0019791667
A8: 6 | B8: Fortunate Son | C8: PDF | D8: Web | E8: Miles | F8: 0.0027893519
A9: 7 | B9: Bohemian Like You | C9: PDF | D9: Web | E9: Matt | F9: 0.0025810185
A10: 8 | B10: Black | C10: PDF | D10: Web | E10: Drew | F10: =VLOOKUP(B10,'Song Tracker'!$A$3:$F$48,6,FALSE) -> 0.0039583333
A11: 9 | B11: Octopus's Garden | C11: PDF | D11: Web | E11: Jack | F11: =VLOOKUP(B11,'Song Tracker'!$A$3:$F$48,6,FALSE) -> 0.0019675926
A12: 10 | B12: Down By The River | C12: PDF | D12: Web | E12: Miles | F12: =VLOOKUP(B12,'Song Tracker'!$A$3:$F$48,6,FALSE) -> 0.0055555556
A13: 11 | B13: Kings Of Ewing | C13: PDF | E13: Drew | F13: 0.0038541667
A14: 12 | B14: Ohio | C14: PDF | D14: Web | E14: Miles | F14: 0.0032291667
A15: 13 | B15: Whipping Post | C15: PDF | D15: Web | E15: Drew | F15: 0.0033217593
A16: 14 | B16: Sympathy For The Devil | C16: PDF | D16: Web | E16: Nate | F16: =VLOOKUP(B16,'Song Tracker'!$A$3:$F$48,6,FALSE) -> 0.0034722222
A17: 15 | B17: Just What I Needed | D17: Web | E17: Matt | F17: =VLOOKUP(B17,'Song Tracker'!$A$3:$F$48,6,FALSE) -> 0.0026041667
A18: 16 | B18: I've Got A Feeling | C18: PDF | D18: Web | E18: Miles | F18: =VLOOKUP(B18,'Song Tracker'!$A$3:$F$48,6,FALSE) -> 0.0025115741
A19: 17 | B19: Don't Look Back In Anger | C19: PDF | D19: Web | E19: Jack | F19: =VLOOKUP(B19,'Song Tracker'!$A$3:$F$48,6,FALSE) -> 0.0033449074
A20: 18 | B20: Riders On The Storm | C20: PDF | D20: Web | E20: Miles | F20: 0.0041319444
A21: 19 | B21: Pink Pony Club | C21: PDF | D21: Web | E21: Matt | F21: 0.0029513889
A22: 20 | B22: Seven Nation Army | C22: PDF | D22: Web | E22: Drew | F22: =VLOOKUP(B22,'Song Tracker'!$A$3:$F$48,6,FALSE) -> 0.0024305556
A23: 22 | B23: Dedicated Follower Of Fashion | C23: PDF | D23: Web | E23: Jack | F23: 0.0017476852
A24: 23 | B24: Midnight Rider | C24: PDF | D24: Web | E24: Drew | F24: 0.0020486111
A25: 24 | B25: Just Like Heaven | C25: PDF | D25: Web | E25: Matt | F25: 0.0025810185
A26: 25 | B26: Rockin' In The Free World | C26: PDF | D26: Web | E26: Miles | F26: 0.0059606481
A27: 26 | B27: Heroes | C27: PDF | D27: Web | E27: Matt | F27: 0.0046875
A28: 27 | B28: Voodoo Child | C28: PDF | D28: Web | E28: Drew | F28: =VLOOKUP(B28,'Song Tracker'!$A$3:$F$48,6,FALSE) -> 0.0034722222
B30: Total Set Length | F30: =SUM(F3:F29) -> 0.081550926

Sheet 2024-08-10 Fat Shallot
A1: 2024-08-10 — Fat Shallot
A2: # | B2: Song | C2: PDF | D2: Web | E2: Vocals | F2: Duration
A3: 1 | B3: Don't Let Me Down | C3: PDF | D3: Web | E3: Miles | F3: 0.0021875
A4: 2 | B4: Won't Back Down | C4: PDF | D4: Web | E4: Miles | F4: 0.0020949074
A5: 3 | B5: No One To Depend On | C5: PDF | D5: Web | E5: Matt | F5: 0.003599537
A6: 4 | B6: Found Out About You | C6: PDF | D6: Web | E6: Drew | F6: 0.0024884259
A7: 5 | B7: Laid | C7: PDF | D7: Web | E7: Jack | F7: 0.0019791667
A8: 6 | B8: Fortunate Son | C8: PDF | D8: Web | E8: Miles | F8: 0.0027893519
A9: 7 | B9: Bohemian Like You | C9: PDF | D9: Web | E9: Matt | F9: 0.0025810185
A10: 8 | B10: Black | C10: PDF | D10: Web | E10: Drew | F10: =VLOOKUP(B10,'Song Tracker'!$A$3:$F$48,6,FALSE) -> 0.0039583333
A11: 9 | B11: Down By The River | C11: PDF | D11: Web | E11: Miles | F11: =VLOOKUP(B11,'Song Tracker'!$A$3:$F$48,6,FALSE) -> 0.0055555556
A12: 10 | B12: Kings Of Ewing | C12: PDF | E12: Drew | F12: 0.0038541667
A13: 11 | B13: Ohio | C13: PDF | D13: Web | E13: Miles | F13: 0.0032291667
A14: 1 | B14: Sympathy For The Devil | C14: PDF | D14: Web | E14: Nate | F14: =VLOOKUP(B14,'Song Tracker'!$A$3:$F$48,6,FALSE) -> 0.0034722222
A15: 2 | B15: Just What I Needed | D15: Web | E15: Matt | F15: =VLOOKUP(B15,'Song Tracker'!$A$3:$F$48,6,FALSE) -> 0.0026041667
A16: 3 | B16: Riders On The Storm | C16: PDF | D16: Web | E16: Miles | F16: 0.0041319444
A17: 4 | B17: Seven Nation Army | C17: PDF | D17: Web | E17: Drew | F17: =VLOOKUP(B17,'Song Tracker'!$A$3:$F$48,6,FALSE) -> 0.0024305556
A18: 5 | B18: Dedicated Follower Of Fashion | C18: PDF | D18: Web | E18: Jack | F18: 0.0017476852
A19: 6 | B19: Midnight Rider | C19: PDF | D19: Web | E19: Drew | F19: 0.0020486111
A20: 7 | B20: Just Like Heaven | C20: PDF | D20: Web | E20: Matt | F20: 0.0025810185
A21: 8 | B21: Whipping Post | C21: PDF | D21: Web | E21: Drew | F21: 0.0033217593
A22: 9 | B22: Rockin' In The Free World | C22: PDF | D22: Web | E22: Miles | F22: 0.0059606481
A23: 10 | B23: Heroes | C23: PDF | D23: Web | E23: Matt | F23: 0.0046875
B25: Total Set Length | F25: =SUM(F3:F24) -> 0.067303241

Sheet 2024-07-13 Chicago Union
A1: 2024-07-13 — Chicago Union (NU Soccer)
A2: # | B2: Song | C2: PDF | D2: Web | E2: Vocals | F2: Duration
A3: 1 | B3: Don't Let Me Down | C3: PDF | D3: Web | E3: Miles | F3: 0.0021875
A4: 2 | B4: Just Like Heaven | C4: PDF | D4: Web | E4: Matt | F4: 0.0025810185
A5: 3 | B5: Laid | C5: PDF | D5: Web | E5: Jack | F5: 0.0019791667
A6: 4 | B6: Fortunate Son | C6: PDF | D6: Web | E6: Miles | F6: 0.0027893519
A7: 5 | B7: Found Out About You | C7: PDF | D7: Web | E7: Drew | F7: 0.0024884259
A8: 6 | B8: No One To Depend On | C8: PDF | D8: Web | E8: Matt | F8: 0.003599537
A9: 7 | B9: Midnight Rider | C9: PDF | D9: Web | E9: Drew | F9: 0.0020486111
A10: 8 | B10: Ohio | C10: PDF | D10: Web | E10: Miles | F10: 0.0032291667
A11: 9 | B11: Down By The River | C11: PDF | D11: Web | E11: Miles | F11: =VLOOKUP(B11,'Song Tracker'!$A$3:$F$48,6,FALSE) -> 0.0055555556
A12: 10 | B12: Whipping Post | C12: PDF | D12: Web | E12: Drew | F12: 0.0033217593
A13: 11 | B13: Heroes | C13: PDF | D13: Web | E13: Matt | F13: 0.0046875
B15: Total Set Length | F15: =SUM(F3:F14) -> 0.034467593

Sheet 2024-06-08 Fat Shallot
A1: 2024-06-08 — Fat Shallot
A2: # | B2: Song | C2: PDF | D2: Web | E2: Vocals | F2: Duration
A3: 1 | B3: Don't Let Me Down | C3: PDF | D3: Web | E3: Miles | F3: 0.0021875
A4: 2 | B4: Won't Back Down | C4: PDF | D4: Web | E4: Miles | F4: 0.0020949074
A5: 3 | B5: No One To Depend On | C5: PDF | D5: Web | E5: Matt | F5: 0.003599537
A6: 4 | B6: Found Out About You | C6: PDF | D6: Web | E6: Drew | F6: 0.0024884259
A7: 5 | B7: Laid | C7: PDF | D7: Web | E7: Jack | F7: 0.0019791667
A8: 6 | B8: Fortunate Son | C8: PDF | D8: Web | E8: Miles | F8: 0.0027893519
A9: 7 | B9: Bohemian Like You | C9: PDF | D9: Web | E9: Matt | F9: 0.0025810185
A10: 8 | B10: Midnight Rider | C10: PDF | D10: Web | E10: Drew | F10: 0.0020486111
A11: 9 | B11: Down By The River | C11: PDF | D11: Web | E11: Miles | F11: =VLOOKUP(B11,'Song Tracker'!$A$3:$F$48,6,FALSE) -> 0.0055555556
A12: 10 | B12: Kings Of Ewing | C12: PDF | E12: Drew | F12: 0.0038541667
A13: 11 | B13: Dedicated Follower Of Fashion | C13: PDF | D13: Web | E13: Jack | F13: 0.0017476852
A14: 12 | B14: Riders On The Storm | C14: PDF | D14: Web | E14: Miles | F14: 0.0041319444
A15: 13 | B15: Just Like Heaven | C15: PDF | D15: Web | E15: Matt | F15: 0.0025810185
A16: 14 | B16: Whipping Post | C16: PDF | D16: Web | E16: Drew | F16: 0.0033217593
A17: 15 | B17: Ohio | C17: PDF | D17: Web | E17: Miles | F17: 0.0032291667
A18: 16 | B18: Rockin' In The Free World | C18: PDF | D18: Web | E18: Miles | F18: 0.0059606481
B20: Total Set Length | F20: =SUM(F3:F19) -> 0.050150463

Sheet 2024-04-27 Lincolnwood
A1: 2024-04-27 — Lincolnwood PTA Spring Fling
A2: # | B2: Song | C2: PDF | D2: Web | E2: Vocals | F2: Duration
A3: 1 | B3: Don't Let Me Down | C3: PDF | D3: Web | E3: Miles | F3: 0.0021875
A4: 2 | B4: Won't Back Down | C4: PDF | D4: Web | E4: Miles | F4: 0.0020949074
A5: 3 | B5: Just Like Heaven | C5: PDF | D5: Web | E5: Matt | F5: 0.0025810185
A6: 4 | B6: Whipping Post | C6: PDF | D6: Web | E6: Drew | F6: 0.0033217593
A7: 5 | B7: Down By The River | C7: PDF | D7: Web | E7: Miles | F7: =VLOOKUP(B7,'Song Tracker'!$A$3:$F$48,6,FALSE) -> 0.0055555556
A8: 6 | B8: Seven Nation Army | C8: PDF | D8: Web | E8: Drew | F8: =VLOOKUP(B8,'Song Tracker'!$A$3:$F$48,6,FALSE) -> 0.0024305556
A9: 7 | B9: Riders On The Storm | C9: PDF | D9: Web | E9: Miles | F9: 0.0041319444
A10: 8 | B10: Heroes | C10: PDF | D10: Web | E10: Matt | F10: 0.0046875
A11: 9 | B11: Fortunate Son | C11: PDF | D11: Web | E11: Miles | F11: 0.0027893519
A12: 10 | B12: Midnight Rider | C12: PDF | D12: Web | E12: Drew | F12: 0.0020486111
A13: 11 | B13: Rockin' In The Free World | C13: PDF | D13: Web | E13: Miles | F13: 0.0059606481
B15: Total Set Length | F15: =SUM(F3:F14) -> 0.037789352

Sheet 2023-09-09 Block Party
A1: 2023-09-09 — Ewing Block Party
A2: # | B2: Song | C2: PDF | D2: Web | E2: Vocals | F2: Duration
A3: 1 | B3: Don't Let Me Down | C3: PDF | D3: Web | E3: Miles | F3: 0.0021875
A4: 2 | B4: Found Out About You | C4: PDF | D4: Web | E4: Drew | F4: 0.0024884259
A5: 3 | B5: Octopus's Garden | C5: PDF | D5: Web | E5: Jack | F5: =VLOOKUP(B5,'Song Tracker'!$A$3:$F$48,6,FALSE) -> 0.0019675926
A6: 4 | B6: Down By The River | C6: PDF | D6: Web | E6: Miles | F6: =VLOOKUP(B6,'Song Tracker'!$A$3:$F$48,6,FALSE) -> 0.0055555556
A7: 5 | B7: Dedicated Follower Of Fashion | C7: PDF | D7: Web | E7: Jack | F7: 0.0017476852
A8: 6 | B8: Whipping Post | C8: PDF | D8: Web | E8: Drew | F8: 0.0033217593
A9: 7 | B9: For What It's Worth | D9: Web | E9: Miles | F9: =VLOOKUP(B9,'Song Tracker'!$A$3:$F$48,6,FALSE) -> 0.0017708333
A10: 8 | B10: Just Like Heaven | C10: PDF | D10: Web | E10: Matt | F10: 0.0025810185
A11: 9 | B11: Won't Back Down | C11: PDF | D11: Web | E11: Miles | F11: 0.0020949074
A12: 10 | B12: Heroes | C12: PDF | D12: Web | E12: Matt | F12: 0.0046875
B14: Total Set Length | F14: =SUM(F3:F13) -> 0.028402778
